Workbook
Name ListCol1: OFFSET(#REF!,0,0,COUNTA(#REF!),1)
Name ListCol2: OFFSET(#REF!,0,0,COUNTA(#REF!),1)
Name ListCol3: OFFSET(#REF!,0,0,COUNTA(#REF!),1)

Sheet 3-24-2026
B2: AIME DAILY REPORT-WORK
B3: Customer: | F3: Work Order / PO # | I3: Report Date:
B4: Job Location:
B5: Job Number: | D5: Report #:
B6: DESCRIPTION OF WORK DONE:
B8: LABOR
B9: NAME | D9: CLASSIFICATION | F9: REG. HRS. | G9: O.T. HRS. | H9: TRAVEL HRS. | I9: REGULAR RATE | J9: AMOUNT
I10: 0 | J10: =IF(F10>0,(F10*'3-24-2026'!I10),0)+IF(G10>0,('3-24-2026'!G10*'3-24-2026'!I10*#REF!),0)+IF(H10>0,('3-24-2026'!H10*'3-24-2026'!I10*#REF!),0)
I11: 0 | J11: =IF(F11>0,(F11*'3-24-2026'!I11),0)+IF(G11>0,('3-24-2026'!G11*'3-24-2026'!I11*#REF!),0)+IF(H11>0,('3-24-2026'!H11*'3-24-2026'!I11*#REF!),0)
I12: 0 | J12: =IF(F12>0,(F12*'3-24-2026'!I12),0)+IF(G12>0,('3-24-2026'!G12*'3-24-2026'!I12*#REF!),0)+IF(H12>0,('3-24-2026'!H12*'3-24-2026'!I12*#REF!),0)
I13: 0 | J13: =IF(F13>0,(F13*'3-24-2026'!I13),0)+IF(G13>0,('3-24-2026'!G13*'3-24-2026'!I13*#REF!),0)+IF(H13>0,('3-24-2026'!H13*'3-24-2026'!I13*#REF!),0)
I14: 0 | J14: =IF(F14>0,(F14*'3-24-2026'!I14),0)+IF(G14>0,('3-24-2026'!G14*'3-24-2026'!I14*#REF!),0)+IF(H14>0,('3-24-2026'!H14*'3-24-2026'!I14*#REF!),0)
I15: 0 | J15: =IF(F15>0,(F15*'3-24-2026'!I15),0)+IF(G15>0,('3-24-2026'!G15*'3-24-2026'!I15*#REF!),0)+IF(H15>0,('3-24-2026'!H15*'3-24-2026'!I15*#REF!),0)
I16: 0 | J16: =IF(F16>0,(F16*'3-24-2026'!I16),0)+IF(G16>0,('3-24-2026'!G16*'3-24-2026'!I16*#REF!),0)+IF(H16>0,('3-24-2026'!H16*'3-24-2026'!I16*#REF!),0)
I17: 0 | J17: =IF(F17>0,(F17*'3-24-2026'!I17),0)+IF(G17>0,('3-24-2026'!G17*'3-24-2026'!I17*#REF!),0)+IF(H17>0,('3-24-2026'!H17*'3-24-2026'!I17*#REF!),0)
I18: 0 | J18: =IF(F18>0,(F18*'3-24-2026'!I18),0)+IF(G18>0,('3-24-2026'!G18*'3-24-2026'!I18*#REF!),0)+IF(H18>0,('3-24-2026'!H18*'3-24-2026'!I18*#REF!),0)
I19: 0 | J19: =IF(F19>0,(F19*'3-24-2026'!I19),0)+IF(G19>0,('3-24-2026'!G19*'3-24-2026'!I19*#REF!),0)+IF(H19>0,('3-24-2026'!H19*'3-24-2026'!I19*#REF!),0)
I20: 0 | J20: =IF(F20>0,(F20*'3-24-2026'!I20),0)+IF(G20>0,('3-24-2026'!G20*'3-24-2026'!I20*#REF!),0)+IF(H20>0,('3-24-2026'!H20*'3-24-2026'!I20*#REF!),0)
I21: 0 | J21: =IF(F21>0,(F21*'3-24-2026'!I21),0)+IF(G21>0,('3-24-2026'!G21*'3-24-2026'!I21*#REF!),0)+IF(H21>0,('3-24-2026'!H21*'3-24-2026'!I21*#REF!),0)
... I23: 0 | J23: =IF(F23>0,(F23*'3-24-2026'!I23),0)+IF(G23>0,('3-24-2026'!G23*'3-24-2026'!I23*#REF!),0)+IF(H23>0,('3-24-2026'!H23*'3-24-2026'!I23*#REF!),0)
D24: Per Diem | I24: =IF(ISERROR(VLOOKUP(D24,#REF!,2,FALSE)),"",VLOOKUP(D24,#REF!,2,FALSE)) | J24: =IF(F24>0,(F24*'3-24-2026'!I24),0)+IF(G24>0,('3-24-2026'!G24*'3-24-2026'!I24*#REF!),0)+IF(H24>0,('3-24-2026'!H24*'3-24-2026'!I24*#REF!),0)
I25: TOTAL LABOR | J25: =ROUND(J10+J11+J12+J13+J14+J15+J16+J17+J18+J19+J20+J21+J22+J23+J24,2)
B27: EQUIPMENT
B28: DESCRIPTION | G28: Quantity | H28: Hours/Days | I28: RATE | J28: AMOUNT
H29: =IF(B29<" ","",VLOOKUP(B29,#REF!,3,FALSE)) | I29: 0 | J29: =IF(G29>0.01,G29*I29,0)
H30: =IF(B30<" ","",VLOOKUP(B30,#REF!,3,FALSE)) | I30: 0 | J30: =IF(G30>0.01,G30*I30,0)
H31: =IF(B31<" ","",VLOOKUP(B31,#REF!,3,FALSE)) | I31: 0 | J31: =IF(G31>0.01,G31*I31,0)
H32: =IF(B32<" ","",VLOOKUP(B32,#REF!,3,FALSE)) | I32: 0 | J32: =IF(G32>0.01,G32*I32,0)
H33: =IF(B33<" ","",VLOOKUP(B33,#REF!,3,FALSE)) | I33: 0 | J33: =IF(G33>0.01,G33*I33,0)
H34: =IF(B34<" ","",VLOOKUP(B34,#REF!,3,FALSE)) | I34: 0 | J34: =IF(G34>0.01,G34*I34,0)
H35: =IF(B35<" ","",VLOOKUP(B35,#REF!,3,FALSE)) | I35: 0 | J35: =IF(G35>0.01,G35*I35,0)
H36: =IF(B36<" ","",VLOOKUP(B36,#REF!,3,FALSE)) | I36: 0 | J36: =IF(G36>0.01,G36*I36,0)
H37: =IF(B37<" ","",VLOOKUP(B37,#REF!,3,FALSE)) | I37: 0 | J37: =IF(G37>0.01,G37*I37,0)
H38: =IF(B38<" ","",VLOOKUP(B38,#REF!,3,FALSE)) | I38: 0 | J38: =IF(G38>0.01,G38*I38,0)
H39: =IF(B39<" ","",VLOOKUP(B39,#REF!,3,FALSE)) | I39: 0 | J39: =IF(G39>0.01,G39*I39,0)
H40: =IF(B40<" ","",VLOOKUP(B40,#REF!,3,FALSE)) | I40: 0 | J40: =IF(G40>0.01,G40*I40,0)
... H43: =IF(B43<" ","",VLOOKUP(B43,#REF!,3,FALSE)) | I43: 0 | J43: =IF(G43>0.01,G43*I43,0)
I44: TOTAL EQUIPMENT | J44: =ROUND(J29+J30+J31+J32+J33+J34+J35+J36+J37+J38+J39+J40+J41+J42+J43,2)
E46: RENTAL EQUIPMENT
C47: MATERIAL & MISCELLANEOUS LIST OF MATERIAL & ATTACH SUPPORTING INVOICES
...
